<?xml version="1.0" ?>
<!--
  Minimal Gazebo world for the integration test.

  - Diff-drive robot (no rendering, no sensors) — proves cmd_vel → physics →
    odometry → bridge → LCM round trip without needing the rendering stack.
  - Uses Bullet (TPE doesn't model wheel friction realistically); we explicitly
    select it so we don't depend on dartsim being installed.

  gz-transport topics:
    cmd_vel  in:  /model/dimos_bot/cmd_vel    gz.msgs.Twist
    odom    out:  /model/dimos_bot/odometry   gz.msgs.Odometry
-->
<sdf version="1.9">
  <world name="dimos_bot_minimal">

    <physics name="1ms" type="ignored">
      <max_step_size>0.001</max_step_size>
      <real_time_factor>0</real_time_factor>
    </physics>

    <plugin filename="gz-sim-physics-system" name="gz::sim::systems::Physics">
      <engine>
        <!-- Match the actual filename built by our flake (libgz-physics7-…). -->
        <filename>gz-physics8-bullet-featherstone-plugin</filename>
      </engine>
    </plugin>
    <plugin filename="gz-sim-user-commands-system"     name="gz::sim::systems::UserCommands"/>
    <plugin filename="gz-sim-scene-broadcaster-system" name="gz::sim::systems::SceneBroadcaster"/>

    <model name="ground_plane">
      <static>true</static>
      <link name="link">
        <collision name="collision">
          <geometry><plane><normal>0 0 1</normal><size>100 100</size></plane></geometry>
        </collision>
      </link>
    </model>

    <model name="dimos_bot">
      <pose>0 0 0.2 0 0 0</pose>

      <link name="chassis">
        <inertial>
          <mass>2.0</mass>
          <inertia><ixx>0.05</ixx><iyy>0.05</iyy><izz>0.05</izz>
                   <ixy>0</ixy><ixz>0</ixz><iyz>0</iyz></inertia>
        </inertial>
        <collision name="c"><geometry><box><size>0.4 0.3 0.2</size></box></geometry></collision>
      </link>

      <link name="left_wheel">
        <pose>0 0.18 -0.05 -1.5707 0 0</pose>
        <inertial><mass>0.2</mass>
          <inertia><ixx>0.001</ixx><iyy>0.001</iyy><izz>0.001</izz>
                   <ixy>0</ixy><ixz>0</ixz><iyz>0</iyz></inertia>
        </inertial>
        <collision name="c"><geometry><cylinder><radius>0.1</radius><length>0.04</length></cylinder></geometry>
          <surface><friction><ode><mu>1.0</mu><mu2>1.0</mu2></ode></friction></surface>
        </collision>
      </link>

      <link name="right_wheel">
        <pose>0 -0.18 -0.05 -1.5707 0 0</pose>
        <inertial><mass>0.2</mass>
          <inertia><ixx>0.001</ixx><iyy>0.001</iyy><izz>0.001</izz>
                   <ixy>0</ixy><ixz>0</ixz><iyz>0</iyz></inertia>
        </inertial>
        <collision name="c"><geometry><cylinder><radius>0.1</radius><length>0.04</length></cylinder></geometry>
          <surface><friction><ode><mu>1.0</mu><mu2>1.0</mu2></ode></friction></surface>
        </collision>
      </link>

      <link name="caster">
        <pose>-0.15 0 -0.1 0 0 0</pose>
        <inertial><mass>0.05</mass>
          <inertia><ixx>1e-4</ixx><iyy>1e-4</iyy><izz>1e-4</izz>
                   <ixy>0</ixy><ixz>0</ixz><iyz>0</iyz></inertia>
        </inertial>
        <collision name="c"><geometry><sphere><radius>0.05</radius></sphere></geometry>
          <surface><friction><ode><mu>0.0</mu><mu2>0.0</mu2></ode></friction></surface>
        </collision>
      </link>

      <joint name="left_wheel_joint" type="revolute">
        <parent>chassis</parent><child>left_wheel</child>
        <axis><xyz>0 0 1</xyz></axis>
      </joint>
      <joint name="right_wheel_joint" type="revolute">
        <parent>chassis</parent><child>right_wheel</child>
        <axis><xyz>0 0 1</xyz></axis>
      </joint>
      <joint name="caster_joint" type="ball">
        <parent>chassis</parent><child>caster</child>
      </joint>

      <plugin filename="gz-sim-diff-drive-system" name="gz::sim::systems::DiffDrive">
        <left_joint>left_wheel_joint</left_joint>
        <right_joint>right_wheel_joint</right_joint>
        <wheel_separation>0.36</wheel_separation>
        <wheel_radius>0.1</wheel_radius>
        <odom_publish_frequency>50</odom_publish_frequency>
        <!-- Defaults: subscribes /model/dimos_bot/cmd_vel,
                       publishes  /model/dimos_bot/odometry -->
        <frame_id>odom</frame_id>
        <child_frame_id>base_link</child_frame_id>
      </plugin>
    </model>
  </world>
</sdf>
